Workbook
Name _FPD: #REF!
Name aa: '[1]Base datos tarifas'!#REF!
Name aa: '[1]Base datos tarifas'!#REF!
Name aa: '[1]Base datos tarifas'!#REF!
Name aa: '[1]Base datos tarifas'!#REF!
Name AccessDataLookup: #REF!
Name ACP: #REF!
Name ADUANAS: 'Sucursal, Aduana, Proveedor'!$E$6:$E$18
Name AEREA: 'Sucursal, Aduana, Proveedor'!$F$15:$F$18
Name BDP: #REF!,#REF!,#REF!
Name CDMX: 'Sucursal, Aduana, Proveedor'!$H$89:$H$98
Name CDP: #REF!
Name CDU: #REF!,#REF!,#REF!
Name CHIHUAHUA: 'Sucursal, Aduana, Proveedor'!$C$89:$C$98
Name CLASEADUANA: 'Sucursal, Aduana, Proveedor'!$F$6:$F$8
Name COMPOS: #REF!
Name CON: #REF!
Name CP: #REF!
Name DEDP: #REF!
Name DORNER: 'Proveedor, Mercancia'!$B$6:$B$13
Name FDP: #REF!
Name FDPP: #REF!
Name FP: #REF!
Name FPD: #REF!
Name FRONTERIZA: 'Sucursal, Aduana, Proveedor'!$F$10:$F$13
Name GAS: #REF!
Name HERMOSILLO: 'Sucursal, Aduana, Proveedor'!$K$89:$K$98
Name HYTROL: 'Proveedor, Mercancia'!$C$6:$C$13
Name IF: #REF!
Name IM: #REF!
Name Importacionaerea: '[1]Base datos tarifas'!#REF!
Name Importacionaerea: '[1]Base datos tarifas'!#REF!
Name Importacionaerea: '[1]Base datos tarifas'!#REF!
Name Importacionaerea: '[1]Base datos tarifas'!#REF!
Name INTECHMOTION: 'Proveedor, Mercancia'!$G$6:$G$13
Name INV: #REF!
Name JUAREZ: 'Sucursal, Aduana, Proveedor'!$D$89:$D$98
Name M: #REF!
Name maintable: #REF!
Name MARITIMA: 'Sucursal, Aduana, Proveedor'!$F$20:$F$21
Name MEXICALI: 'Sucursal, Aduana, Proveedor'!$L$89:$L$98
Name MIR: 'Proveedor, Mercancia'!$E$6:$E$13
Name MONTERREY: 'Sucursal, Aduana, Proveedor'!$G$89:$G$98
Name MTY: '[1]Base datos tarifas'!#REF!
Name MTY: '[1]Base datos tarifas'!#REF!
Name MTY: '[1]Base datos tarifas'!#REF!
Name MTY: '[1]Base datos tarifas'!#REF!
Name NOGALES: 'Sucursal, Aduana, Proveedor'!$J$89:$J$98
Name noooo: '[1]Base datos tarifas'!#REF!
Name noooo: '[1]Base datos tarifas'!#REF!
Name noooo: '[1]Base datos tarifas'!#REF!
Name noooo: '[1]Base datos tarifas'!#REF!
Name OFP: #REF!
Name P: #REF!
Name Proveedor: '[1]Base datos tarifas'!#REF!
Name Proveedor: '[1]Base datos tarifas'!#REF!
Name Proveedor: '[1]Base datos tarifas'!#REF!
Name Proveedor: '[1]Base datos tarifas'!#REF!
Name PROVEEDORES: 'Proveedor, Mercancia'!$A$6:$A$30
Name PUEBLA: 'Sucursal, Aduana, Proveedor'!$I$89:$I$98

Sheet Proveedor, Mercancia
A1: Fracciones Arancelarias por Proveedor
A2: Versión | B2: Revisión | C2: Fecha de actualizacion
A3: 1 | B3: 0
A5: Proveedor | B5: Dorner | C5: Hytrol | D5: Southworth | E5: MiR | F5: UR | G5: Intechmotion | H5: OnRobot | I5: Robotiq | J5: Dellner | K5: Italvibras
A6: Dorner | B6: Transportador de banda con accesorios | C6: Partes para transportador | D6: Mesa de elevación con sus accesorios | E6: Cargador de baterías 48v 12a | F6: Brazo robotico para uso industrial con accesorios para su instalacion y funcionamiento | G6: Transportador de cadena plástica
A7: Hytrol | B7: Banda de plastico con refuerzo textil | C7: Transportador de banda con accesorios | D7: Carretilla manual con sistema de elevacion | E7: Juego de baterías recargables de litio con sus accesorios para instalación | F7: Partes para robot industrial | G7: Perfil de aluminio
A8: Southworth | B8: Motorreductor | C8: Transportador de gravedad con accesorios | E8: Robot industrial para manipulación de mercancia con sus accesorios
A9: MiR | B9: Partes para transportador | C9: Transportador de rodillos con accesorios | E9: Partes para robot industrial
A10: UR | C10: Rodillo para transportador | E10: Circuitos Modulares
A11: Intechmotion | C11: Banda transportadora de plástico

Sheet Fraccion Arancelaria
A1: Catálogo de Fracciones Arancelarias
A2: Versión | B2: Revisión | C2: Fecha de actualizacion
A3: 1 | B3: 0
A5: Versión | B5: Revisión
A6: CERTIFICADO DE ORIGEN | B6: SI
B7: NO
A9: Proveedores | B9: Parte / Equipo | C9: Fracción Arancelaria | D9: DESCRIPCIÓN EN PEDIMENTO | E9: Tasa IGI | F9: RRNA
A10: DELLNER | B10: ACOPLAMIENTO FLEXIBLE PARA EMBRAGUE | C10: 8483609900 | D10: Acoplamiento flexible para embrague | E10: 0.1
A11: ACCESORIOS | B11: IN-IN GUSSET & SET SCREWS 10MM | C11: 7616999999 | D11: Manufactura de aluminio | E11: 0.15
A12: MiR | B12: ROBOTS INDUSTRIALES MIR | C12: 8428700100 | D12: Robot industrial para manipulación de mercancia con sus accesorios | E12: 0.15
A13: MiR | B13: ROBOTS INDUSTRIALES MIR | C13: 8428700100 | D13: Robot industrial para manipulación de mercancia con sus accesorios | E13: 0.15
A14: MiR | B14: ROBOTS INDUSTRIALES MIR | C14: 8428700100 | D14: Robot industrial para manipulación de mercancia con sus accesorios | E14: 0.15
A15: SOUTHWORTH | B15: MESAS SOUTHWORTH | C15: 8428909999 | D15: Mesa de elevación con sus accesorios | E15: 0.15
A16: SOUTHWORTH | B16: CARRETILLA MANUAL | C16: 8427909100 | D16: Carretilla manual con sistema de elevacion | E16: 0.15
A17: ACCESORIOS | B17: SUJETADOR DE METAL | C17: 7326909999 | D17: Manufactura de metal | E17: 0.25
A18: ACCESORIOS | B18: TORNILLOS | C18: 7318159908 | D18: Tornillos con diámetro igual o superior a 19.1 mm (¾ pulgada) y longitud igual o superior a 152.4 mm | E18: 0.25
A19: ACCESORIOS | B19: TORNILLOS | C19: 7318159907 | D19: Tornillos con diámetro igual o superior a 19.1 mm (¾ pulgada) y longitud inferior a 152.4 mm | E19: 0.25
A20: ACCESORIOS | B20: TORNILLOS | C20: 7318159906 | D20: Tornillos con diámetro igual o superior a 6.4 mm (¼ pulgada) pero inferior a 19.1 mm (¾ pulgada) y longitud igual o superior a 152.4 mm | E20: 0.25
A21: ACCESORIOS | B21: TORNILLOS | C21: 7318159905 | D21: Tornillos con diámetro igual o superior a 6.4 mm (¼ pulgada) pero inferior a 19.1 mm (¾ pulgada) y longitud inferior a 152.4 mm | E21: 0.25
... A51: UNIVERSAL ROBOTS | B51: BRAZOS ROBOTICOS UR | C51: 8479500100 | D51: Brazo robotico para uso industrial con accesorios para su instalacion y funcionamiento | E51: 0
A52: DORNER | B52: PARTES PARA TRANSPORTADOR DORNER | D52: Partes para transportador
A53: UNIVERSAL ROBOTS | B53: PARTES PARA ROBOT | C53: 8479901899 | D53: Partes para robot industrial | E53: 0
A54: MiR | B54: PARTES PARA ROBOT | C54: 8479901899 | D54: Partes para robot industrial | E54: 0

Sheet Bodega, Recinto, A.A.
A1: Tarifarios de Agencia Aduanal, Bodega y Recinto
A2: Versión | C2: Revisión | D2: Fecha de actualizacion
A3: 1 | C3: 1
A5: VALOR MERCANCIA | B5: CANTIDAD BULTOS | C5: PESO LBS | D5: TIPO EMBARQUE | E5: PROVEEDOR
A6: =GUIALOG!$P$55 -> 123590 | B6: =GUIALOG!$P$88 -> 3 | C6: =GUIALOG!$P$89 -> Embalaje URe | D6: =GUIALOG!P113 -> FTL 53´ | E6: =GUIALOG!P110 -> UR
A9: COSTO BODEGA POR AGENCIA ADUANAL ZONA - SUC
A10: ADUANA | B10: ZONA | C10: AGENCIA | D10: AGENCIA | E10: FORMULA
B11: ZONA | C11: AGENCIA | D11: AGENCIA
A12: El Paso | B12: A | C12: A1, A3, A4 | D12: MARON | E12: =G29 -> 400
A13: Laredo | B13: B | C13: B2, B3 | D13: 1780 | E13: =G30 -> 700
A14: Nogales | B14: C | C14: C4 | D14: PRL | E14: =G31 -> 400
A15: San Diego | B15: D | C15: D5 | D15: SICA | E15: =G32 -> 750
A16: Monterrey | B16: E | C16: E2,E3 | D16: PALCO | E16: =G33 -> 250
A17: AICM | B17: F | C17: F3 | D17: PALCO | E17: =G34 -> 250
A18: Cd. Juarez | B18: G | C18: G1, G2, G3 | D18: MARON | E18: =G35 -> 138.88889
A19: Tijuana | B19: H | C19: H4, H5 | D19: SICA | E19: =G36 -> 138.88889
A20: Altamira | B20: I | C20: I1, I2, I3, I4, I5 | D20: PALCO | E20: =G37 -> 500
A21: Manzanillo | B21: J | C21: J1, J2, J3, J4, J5 | D21: ALIANZA | E21: =G38 -> 500
A24: TARIFAS DE BODEGAS Y RECINTOS AEREOS
A25: ADUANA | B25: AGENCIA | C25: TARIFA MIN. IMPORTACION | D25: TARIFA POR CONSOLIDADO | E25: TARIFA CARGA COMPLETA | F25: TRAMITE IN-BOND (Adicional) | G25: CALCULO COSTO POR OPERACIÓN
A26: Fronteriza | C26: 1 - 3 SKD | D26: 3 - 9 SKD | E26: 10+ SKD
A27: Aerea | C27: < 500KG | D27: 500KG | E27: 1000KG
A28: Maritima | C28: LCL < 1000 KG | D28: LCL > 1000 KG | E28: FCL <> 20000 KG
A29: El Paso | B29: MARON | C29: 200 | D29: 250 | E29: 400 | F29: 165 | G29: =IF($C$6<1000,C29,IF(AND($C$6>999,$C$6<2000),D29,E29)) -> 400
A30: Laredo | B30: 1780 | C30: 400 | D30: 550 | E30: 700 | F30: 165 | G30: =IF($C$6<1000,C30,IF(AND($C$6>999,$C$6<2000),D30,E30)) -> 700
A31: Nogales | B31: PRL | C31: 200 | D31: 250 | E31: 400 | F31: 165 | G31: =IF($C$6<1000,C31,IF(AND($C$6>999,$C$6<2000),D31,E31)) -> 400
A32: San Diego | B32: SICA | C32: 230 | D32: 350 | E32: 750 | F32: 295 | G32: =IF($C$6<1000,C32,IF(AND($C$6>999,$C$6<2000),D32,E32)) -> 750
A33: Monterrey | B33: PALCO | C33: 138.88889 | D33: 194.44444 | E33: 250 | F33: 0 | G33: =IF($C$6<1000,C33,IF(AND($C$6>999,$C$6<2000),D33,E33)) -> 250
A34: AICM | B34: PALCO | C34: 138.88889 | D34: 194.44444 | E34: 250 | F34: 0 | G34: =IF($C$6<1000,C34,IF(AND($C$6>999,$C$6<2000),D34,E34)) -> 250
A35: Cd. Juarez | B35: MARON | C35: 61.111111 | D35: 105.55556 | E35: 138.88889 | F35: 0 | G35: =IF($C$6<1000,C35,IF(AND($C$6>999,$C$6<2000),D35,E35)) -> 138.88889
A36: Tijuana | B36: SICA | C36: 61.111111 | D36: 105.55556 | E36: 138.88889 | F36: 0 | G36: =IF($C$6<1000,C36,IF(AND($C$6>999,$C$6<2000),D36,E36)) -> 138.88889
A37: Altamira | B37: PALCO | C37: =5000/18 -> 277.77778 | D37: =7000/18 -> 388.88889 | E37: =9000/18 -> 500 | F37: 0 | G37: =IF($C$6<1000,C37,IF(AND($C$6>999,$C$6<2000),D37,E37)) -> 500
A38: Manzanillo | B38: ALIANZA | C38: =5000/18 -> 277.77778 | D38: =7000/18 -> 388.88889 | E38: =9000/18 -> 500 | F38: 0 | G38: =IF($C$6<1000,C38,IF(AND($C$6>999,$C$6<2000),D38,E38)) -> 500
A42: HONORARIOS AGENCIA ADUANAL POR ZONA - SUC
A43: ADUANA | B43: ZONA | C43: AGENCIA | D43: AGENCIA | E43: FORMULA
B44: ZONA | C44: AGENCIA | D44: AGENCIA
A45: El Paso | B45: A | C45: A1, A3, A4 | D45: MARON | E45: =(0.0035*$A$6)+40+80 -> 552.565
A46: Laredo | B46: B | C46: B2, B3 | D46: 1780 | E46: =(180+(0.0045*$A$6)) -> 736.155
A47: Nogales | B47: C | C47: C4 | D47: PRL | E47: =($A$6*0.0125)+116 -> 1660.875
A48: San Diego | B48: D | C48: D5 | D48: SICA | E48: =IF($A$6<5000,160,IF($A$6<8000,167,IF($A$6<10000,197,IF($A$6<12000,233,IF($A$6<15000,260,IF($A$6<25000,321,($A$6*0.005))))))) -> 617.95
...

Sheet Sucursal, Aduana, Proveedor
A1: Catálogo de sucursales, aduanas y proveedores, de importacion terrestre
A2: Versión | C2: Revisión | F2: Fecha de actualizacion
A3: 1 | C3: 0
A5: Sucursales | B5: ZONA # | C5: Proveedor | D5: # | E5: Aduanas | F5: Tipo de Aduana | G5: ZONA #
A6: Chihuahua | B6: 1 | C6: Dorner | D6: 0.01 | E6: El Paso | F6: Fronteriza | G6: X
A7: Juarez | B7: 1 | C7: Hytrol | D7: 0.02 | E7: Laredo | F7: Aerea | G7: Y
A8: Saltillo | B8: 2 | C8: Southworth | D8: 0.03 | E8: Nogales | F8: Maritima | G8: Z
A9: Torreon | B9: 2 | C9: MiR | D9: 0.04 | E9: San Diego | F9: Fronteriza
A10: Monterrey | B10: 2 | C10: UR | D10: 0.05 | E10: Monterrey | F10: El Paso | G10: A
A11: CDMX | B11: 2 | C11: Qimarox | D11: 0.06 | E11: AICM | F11: Laredo | G11: B
A12: Puebla | B12: 3 | C12: Intechmotion | D12: 0.07 | E12: Cd. Juarez | F12: Nogales | G12: C
A13: Nogales | B13: 4 | D13: 0.08 | E13: Tijuana | F13: San Diego | G13: D
A14: Hermosillo | B14: 4 | D14: 0.09 | E14: Altamira | F14: Aerea
A15: Mexicali | B15: 5 | D15: 0.1 | E15: Manzanillo | F15: Monterrey | G15: E
A16: Tijuana | B16: 5 | D16: 0.11 | F16: AICM | G16: F
D17: 0.12 | F17: Cd. Juarez | G17: G
F18: Tijuana | G18: H
F19: Maritima
F20: Altamira | G20: I
F21: Manzanillo | G21: J
W24: *Hay dos formas de definir la aduana de entrada: i. Por el destino de la sucursal, ii. Por el origine del proveedor y destino de sucursal
A28: TABLAS DE CORRELACION SUCURSAL - PROVEEDOR
A29: PROV/SUC | C29: Chihuahua | D29: Cd. Juarez | E29: Saltillo | F29: Torreon | G29: Monterrey | H29: CDMX | I29: Puebla | J29: Nogales | K29: Hermosillo | L29: Mexicali | M29: Tijuana
A30: Dorner | C30: =$B$6+D6 -> 1.01 | D30: =$B$7+D6 -> 1.01 | E30: =$B$8+D6 -> 2.01 | F30: =$B$9+D6 -> 2.01 | G30: =$B$10+D6 -> 2.01 | H30: =$B$11+D6 -> 2.01 | I30: =$B$12+D6 -> 3.01 | J30: =$B$13+D6 -> 4.01 | K30: =$B$14+D6 -> 4.01 | L30: 5.01 | M30: =$B$16+D6 -> 5.01
A31: Hytrol | C31: =$B$6+D7 -> 1.02 | D31: =$B$7+D7 -> 1.02 | E31: =$B$8+D7 -> 2.02 | F31: =$B$9+D7 -> 2.02 | G31: =$B$10+D7 -> 2.02 | H31: =$B$11+D7 -> 2.02 | I31: =$B$12+D7 -> 3.02 | J31: =$B$13+D7 -> 4.02 | K31: =$B$14+D7 -> 4.02 | L31: 5.02 | M31: =$B$16+D7 -> 5.02
A32: Southworth | C32: =$B$6+D8 -> 1.03 | D32: =$B$7+D8 -> 1.03 | E32: =$B$8+D8 -> 2.03 | F32: =$B$9+D8 -> 2.03 | G32: =$B$10+D8 -> 2.03 | H32: =$B$11+D8 -> 2.03 | I32: =$B$12+D8 -> 3.03 | J32: =$B$13+D8 -> 4.03 | K32: =$B$14+D8 -> 4.03 | L32: 5.03 | M32: =$B$16+D8 -> 5.03
A33: MiR | C33: =$B$6+D9 -> 1.04 | D33: =$B$7+D9 -> 1.04 | E33: =$B$8+D9 -> 2.04 | F33: =$B$9+D9 -> 2.04 | G33: =$B$10+D9 -> 2.04 | H33: =$B$11+D9 -> 2.04 | I33: =$B$12+D9 -> 3.04 | J33: =$B$13+D9 -> 4.04 | K33: =$B$14+D9 -> 4.04 | L33: 5.04 | M33: =$B$16+D9 -> 5.04
A34: UR | C34: =$B$6+D10 -> 1.05 | D34: =$B$7+D10 -> 1.05 | E34: =$B$8+D10 -> 2.05 | F34: =$B$9+D10 -> 2.05 | G34: =$B$10+D10 -> 2.05 | H34: =$B$11+D10 -> 2.05 | I34: =$B$12+D10 -> 3.05 | J34: =$B$13+D10 -> 4.05 | K34: =$B$14+D10 -> 4.05 | L34: 5.05 | M34: =$B$16+D10 -> 5.05
A35: Qimarox | C35: =$B$6+D11 -> 1.06 | D35: =$B$7+D11 -> 1.06 | E35: =$B$8+D11 -> 2.06 | F35: =$B$9+D11 -> 2.06 | G35: =$B$10+D11 -> 2.06 | H35: =$B$11+D11 -> 2.06 | I35: =$B$12+D11 -> 3.06 | J35: =$B$13+D11 -> 4.06 | K35: =$B$14+D11 -> 4.06 | L35: 5.06 | M35: =$B$16+D11 -> 5.06
A36: Intechmotion | C36: =$B$6+D12 -> 1.07 | D36: =$B$7+D12 -> 1.07 | E36: =$B$8+D12 -> 2.07 | F36: =$B$9+D12 -> 2.07 | G36: =$B$10+D12 -> 2.07 | H36: =$B$11+D12 -> 2.07 | I36: =$B$12+D12 -> 3.07 | J36: =$B$13+D12 -> 4.07 | K36: =$B$14+D12 -> 4.07 | L36: 5.07 | M36: =$B$16+D12 -> 5.07
A37: TABLAS DE CORRELACION SUCURSAL - PROVEEDOR
A38: PROV/SUC | C38: Chihuahua | D38: Cd. Juarez | E38: Saltillo | F38: Torreon | G38: Monterrey | H38: CDMX | I38: Puebla | J38: Nogales | K38: Hermosillo | L38: Mexicali | M38: Tijuana
A39: Dorner | C39: =$B$6+D15 -> 1.1 | D39: =$B$7+D15 -> 1.1 | E39: =$B$8+D15 -> 2.1 | F39: =$B$9+D15 -> 2.1 | G39: =$B$10+D15 -> 2.1 | H39: =$B$11+D15 -> 2.1 | I39: =$B$12+D15 -> 3.1 | J39: =$B$13+D15 -> 4.1 | K39: =$B$14+D15 -> 4.1 | L39: 5.01 | M39: =$B$16+D15 -> 5.1
A40: Hytrol | C40: =$B$6+D16 -> 1.11 | D40: =$B$7+D16 -> 1.11 | E40: =$B$8+D16 -> 2.11 | F40: =$B$9+D16 -> 2.11 | G40: =$B$10+D16 -> 2.11 | H40: =$B$11+D16 -> 2.11 | I40: =$B$12+D16 -> 3.11 | J40: =$B$13+D16 -> 4.11 | K40: =$B$14+D16 -> 4.11 | L40: 5.02 | M40: =$B$16+D16 -> 5.11
A41: Southworth | C41: =$B$6+D17 -> 1.12 | D41: =$B$7+D17 -> 1.12 | E41: =$B$8+D17 -> 2.12 | F41: =$B$9+D17 -> 2.12 | G41: =$B$10+D17 -> 2.12 | H41: =$B$11+D17 -> 2.12 | I41: =$B$12+D17 -> 3.12 | J41: =$B$13+D17 -> 4.12 | K41: =$B$14+D17 -> 4.12 | L41: 5.03 | M41: =$B$16+D17 -> 5.12
A42: MiR | C42: =$B$6+D18 -> 1 | D42: =$B$7+D18 -> 1 | E42: =$B$8+D18 -> 2 | F42: =$B$9+D18 -> 2 | G42: =$B$10+D18 -> 2 | H42: =$B$11+D18 -> 2 | I42: =$B$12+D18 -> 3 | J42: =$B$13+D18 -> 4 | K42: =$B$14+D18 -> 4 | L42: 5.04 | M42: =$B$16+D18 -> 5
A43: UR | C43: =$B$6+D19 -> 1 | D43: =$B$7+D19 -> 1 | E43: =$B$8+D19 -> 2 | F43: =$B$9+D19 -> 2 | G43: =$B$10+D19 -> 2 | H43: =$B$11+D19 -> 2 | I43: =$B$12+D19 -> 3 | J43: =$B$13+D19 -> 4 | K43: =$B$14+D19 -> 4 | L43: 5.05 | M43: =$B$16+D19 -> 5
A44: Qimarox | C44: =$B$6+D20 -> 1 | D44: =$B$7+D20 -> 1 | E44: =$B$8+D20 -> 2 | F44: =$B$9+D20 -> 2 | G44: =$B$10+D20 -> 2 | H44: =$B$11+D20 -> 2 | I44: =$B$12+D20 -> 3 | J44: =$B$13+D20 -> 4 | K44: =$B$14+D20 -> 4 | L44: 5.06 | M44: =$B$16+D20 -> 5
A45: Intechmotion | C45: =$B$6+D21 -> 1 | D45: =$B$7+D21 -> 1 | E45: =$B$8+D21 -> 2 | F45: =$B$9+D21 -> 2 | G45: =$B$10+D21 -> 2 | H45: =$B$11+D21 -> 2 | I45: =$B$12+D21 -> 3 | J45: =$B$13+D21 -> 4 | K45: =$B$14+D21 -> 4 | L45: 5.07 | M45: =$B$16+D21 -> 5
A48: CORRELACION ADUANAS - SUCURSAL - PROVEEDOR
...

Sheet Fletes Impo
A1: Tarifarios de fletes de origen y fletes de importacion
A2: Versión | C2: Revisión | D2: Fecha de actualizacion
A3: 1 | C3: 1
A6: CARATULA DE EJERCICIO ACTUAL
A7: VALOR MERCANCIA | B7: CANTIDAD BULTOS | C7: PESO LBS | D7: TIPO EMBARQUE
A8: =GUIALOG!$P$55 -> 123590 | B8: =GUIALOG!$P$88 -> 3 | C8: =GUIALOG!$P$89 -> Embalaje URe | D8: =GUIALOG!S88 -> FTL 53´
A11: TIPOS DE TRANSPORTE
A12: FTL 53´
A13: RABON 20´
A14: 3.5 T
A15: CONSOLIDADO
A18: Sucursales | B18: ZONA # | C18: Proveedor | D18: # | E18: Aduanas | F18: Tipo de Aduana | G18: ZONA #
A19: Chihuahua | B19: 1 | C19: Dorner | D19: 0.01 | E19: El Paso | F19: Fronteriza | G19: X
A20: Juarez | B20: 1 | C20: Hytrol | D20: 0.02 | E20: Laredo | F20: Aerea | G20: Y
A21: Saltillo | B21: 2 | C21: Southworth | D21: 0.03 | E21: Nogales | F21: Maritima | G21: Z
A22: Torreon | B22: 2 | C22: MiR | D22: 0.04 | E22: San Diego | F22: Fronteriza
A23: Monterrey | B23: 2 | C23: UR | D23: 0.05 | E23: Monterrey | F23: El Paso | G23: A
A24: CDMX | B24: 2 | C24: Qimarox | D24: 0.06 | E24: AICM | F24: Laredo | G24: B
A25: Puebla | B25: 3 | C25: Intechmotion | D25: 0.07 | E25: Cd. Juarez | F25: Nogales | G25: C
A26: Nogales | B26: 4 | D26: 0.08 | E26: Tijuana | F26: San Diego | G26: D
A27: Hermosillo | B27: 4 | D27: 0.09 | E27: Altamira | F27: Aerea
A28: Mexicali | B28: 5 | D28: 0.1 | E28: Manzanillo | F28: Monterrey | G28: E
A29: Tijuana | B29: 5 | D29: 0.11 | F29: AICM | G29: F
D30: 0.12 | F30: Cd. Juarez | G30: G
F31: Tijuana | G31: H
F32: Maritima
F33: Altamira | G33: I
F34: Manzanillo | G34: J
A43: RUTAS IMPORTACION ADUANA-SUCURSAL DEDICADOS | F43: RUTAS IMPORTACION ADUANA-SUCURSAL CONSOLIDADO
A44: PROVEEDOR | B44: SUCURSAL DESTINO | C44: RUTA | D44: DEDICADO | F44: PROVEEDOR | G44: SUCURSAL DESTINO | H44: RUTA | I44: CONSOLIDADO
A45: El Paso | B45: Chihuahua | C45: =CONCATENATE(A45,B45,) -> El PasoChihuahua | F45: El Paso | G45: Chihuahua | H45: =CONCATENATE(F45,G45,) -> El PasoChihuahua | I45: =2*4 -> 8
A46: El Paso | B46: Juarez | C46: =CONCATENATE(A46,B46,) -> El PasoJuarez | F46: El Paso | G46: Juarez | H46: =CONCATENATE(F46,G46,) -> El PasoJuarez | I46: 15
A47: El Paso | B47: Puebla | C47: =CONCATENATE(A47,B47,) -> El PasoPuebla | F47: El Paso | G47: Puebla | H47: =CONCATENATE(F47,G47,) -> El PasoPuebla | I47: 135
A48: El Paso | B48: Nogales | C48: =CONCATENATE(A48,B48,) -> El PasoNogales | F48: El Paso | G48: Nogales | H48: =CONCATENATE(F48,G48,) -> El PasoNogales | I48: 4741
A49: El Paso | B49: Hermosillo | C49: =CONCATENATE(A49,B49,) -> El PasoHermosillo | F49: El Paso | G49: Hermosillo | H49: =CONCATENATE(F49,G49,) -> El PasoHermosillo | I49: 4
A50: Laredo | B50: Saltillo | C50: =CONCATENATE(A50,B50,) -> LaredoSaltillo | F50: Laredo | G50: Saltillo | H50: =CONCATENATE(F50,G50,) -> LaredoSaltillo | I50: 158
A51: Laredo | B51: Torreon | C51: =CONCATENATE(A51,B51,) -> LaredoTorreon | F51: Laredo | G51: Torreon | H51: =CONCATENATE(F51,G51,) -> LaredoTorreon | I51: 164
A52: Laredo | B52: Monterrey | C52: =CONCATENATE(A52,B52,) -> LaredoMonterrey | F52: Laredo | G52: Monterrey | H52: =CONCATENATE(F52,G52,) -> LaredoMonterrey | I52: 46487
A53: Laredo | B53: CDMX | C53: =CONCATENATE(A53,B53,) -> LaredoCDMX | F53: Laredo | G53: CDMX | H53: =CONCATENATE(F53,G53,) -> LaredoCDMX | I53: 77
A54: Laredo | B54: Puebla | C54: =CONCATENATE(A54,B54,) -> LaredoPuebla | F54: Laredo | G54: Puebla | H54: =CONCATENATE(F54,G54,) -> LaredoPuebla | I54: 999
...

Sheet Fletes Proveedor
A1: Tarifarios de fletes de origen y fletes de importacion
A2: Versión | C2: Revisión | D2: Fecha de actualizacion
A3: 1 | C3: 1
A5: CARATULA DE EJERCICIO ACTUAL
A6: VALOR MERCANCIA | B6: CANTIDAD BULTOS | C6: PESO LBS | D6: TIPO EMBARQUE
A7: =GUIALOG!$P$55 -> 123590 | B7: =GUIALOG!$P$88 -> 3 | C7: =GUIALOG!$P$89 -> Embalaje URe | D7: =GUIALOG!P87 -> RABON 20´
A10: TIPOS DE TRANSPORTE
A11: FTL 53´
A12: RABON 20´
A13: 3.5 T
A14: CONSOLIDADO
A17: Sucursales | B17: ZONA # | C17: Proveedor | D17: # | E17: Aduanas | F17: Tipo de Aduana | G17: ZONA #
A18: Chihuahua | B18: 1 | C18: Dorner | D18: 0.01 | E18: El Paso | F18: Fronteriza | G18: X
A19: Juarez | B19: 1 | C19: Hytrol | D19: 0.02 | E19: Laredo | F19: Aerea | G19: Y
A20: Saltillo | B20: 2 | C20: Southworth | D20: 0.03 | E20: Nogales | F20: Maritima | G20: Z
A21: Torreon | B21: 2 | C21: MiR | D21: 0.04 | E21: San Diego | F21: Fronteriza
A22: Monterrey | B22: 2 | C22: UR | D22: 0.05 | E22: Monterrey | F22: El Paso | G22: A
A23: CDMX | B23: 2 | C23: Qimarox | D23: 0.06 | E23: AICM | F23: Laredo | G23: B
A24: Puebla | B24: 3 | C24: Intechmotion | D24: 0.07 | E24: Cd. Juarez | F24: Nogales | G24: C
A25: Nogales | B25: 4 | D25: 0.08 | E25: Tijuana | F25: San Diego | G25: D
A26: Hermosillo | B26: 4 | D26: 0.09 | E26: Altamira | F26: Aerea
A27: Mexicali | B27: 5 | D27: 0.1 | E27: Manzanillo | F27: Monterrey | G27: E
A28: Tijuana | B28: 5 | D28: 0.11 | F28: AICM | G28: F
D29: 0.12 | F29: Cd. Juarez | G29: G
F30: Tijuana | G30: H
F31: Maritima
F32: Altamira | G32: I
F33: Manzanillo | G33: J
A40: RANGO DE PESO
A41: DEDICADO
A42: Embalaje MIR250
A43: Embalaje MIR600
A44: Embalaje MIR1350
A45: Embalaje URe
A46: Embalaje UR20
A47: 100
A48: 200
A49: 300
A50: 400
A51: 500
...

Sheet GUIALOG
A5: Instrucciones
A23: Seccion I. Informacion General
J29: Juarez
I30: Sucursal
J32: UR
I33: Proveedor | O33: INFORMACION SECCION I | S33: BUSQUEDA DE A.A.
O34: SUCURSAL | P34: =J29 -> Juarez | S34: COINCIDIR ADUANA (Fila) | T34: =MATCH($P$38,'Sucursal, Aduana, Proveedor'!A103:A112,0) -> 1
J35: Juarez | O35: DESTINO | P35: =J35 -> Juarez | S35: COINCIDIR A.A. (Columna) | T35: =MATCH($O$39,'Sucursal, Aduana, Proveedor'!A102:D102,0) -> 4
I36: Destino | O36: PROVEEDOR | P36: =J32 -> UR | S36: INDICE | T36: =INDEX('Sucursal, Aduana, Proveedor'!A103:D112,MATCH($P$38,'Sucursal, Aduana, Proveedor'!A103:A112,0),MATCH($O$39,'Sucursal, Aduana, Proveedor'!A102:D102,0)) -> MARON
O37: TIPO DE RUTA
J38: El Paso | O38: ADUANA | P38: =J38 -> El Paso | S38: BUSQUEDA DE ADUANA
I39: Aduana Impo | O39: AGENCIA | P39: =IF(P38='Sucursal, Aduana, Proveedor'!A103,'Sucursal, Aduana, Proveedor'!D103,(IF(P38='Sucursal, Aduana, Proveedor'!A104,'Sucursal, Aduana, Proveedor'!D104,(IF(P38='Sucursal, Aduana, Proveedor'!A105,'Sucursal, Aduana, Proveedor'!D105,(IF(P38='Sucursal, Aduana, Proveedor'!A106,'Sucursal, Aduana, Proveedor'!D106,(IF(P38='Sucursal, Aduana, Proveedor'!A107,'Sucursal, Aduana, Proveedor'!D107,(IF(P38='Sucursal, Aduana, Proveedor'!A108,'Sucursal, Aduana, Proveedor'!D108,(IF(P38='Sucursal, Aduana, Proveedor'!A109,'Sucursal, Aduana, Proveedor'!D109,(IF(P38='Sucursal, Aduana, Proveedor'!A110,'Sucursal, Aduana, Proveedor'!D110,(IF(P38='Sucursal, Aduana, Proveedor'!A111,'Sucursal, Aduana, Proveedor'!D111,(IF(P38='Sucursal, Aduana, Proveedor'!A112,'Sucursal, Aduana, Proveedor'!D112,"P/D"))))))))))))))))))) -> MARON | S39: COINCIDIR ADUANA (Fila) | T39: =MATCH($P$38,'Sucursal, Aduana, Proveedor'!A103:A117,0) -> 1
S40: COINCIDIR A.A. (Columna) | T40: =MATCH($O$39,'Sucursal, Aduana, Proveedor'!A107:D107,0) -> #N/A
S41: INDICE | T41: =INDEX('Sucursal, Aduana, Proveedor'!A108:D117,MATCH($P$38,'Sucursal, Aduana, Proveedor'!A108:A117,0),MATCH($O$39,'Sucursal, Aduana, Proveedor'!A107:D107,0)) -> #N/A
A44: Seccion II. Informacion de Mercancias
O49: INFORMACION SECCION II | S49: BUSQUEDA DE IGI
O50: SUCURSAL | P50: =P34 -> Juarez | S50: COINCIDIR MATERIAL (Fila) | T50: =MATCH($P$54,'Fraccion Arancelaria'!$D$10:$D$119,0) -> 3
J51: =P53 -> UR | O51: ADUANA | P51: =P38 -> El Paso | S51: COINCIDIR IGI (Columna) | T51: =MATCH($O$56,'Fraccion Arancelaria'!$D$9:E9,0) -> 2
I52: Proveedor | O52: A.A. | P52: =P39 -> MARON | S52: INDICE | T52: =INDEX('Fraccion Arancelaria'!$D$10:$E$119,MATCH($P$54,'Fraccion Arancelaria'!$D$10:$D$119,0),2) -> 0.15
O53: PROVEEDOR | P53: =P36 -> UR
J54: Robot industrial para manipulación de mercancia con sus accesorios | O54: PRODUCTO | P54: =J54 -> Robot industrial para manipulación de mercancia con sus accesorios
I55: Mercancía | O55: VALOR MERCANCIA | P55: =J57 -> 123590
O56: TASA IGI | P56: =T52 -> 0.15
J57: 123590 | O57: CERTIFICADO ORIGEN | P57: =J60 -> SI
I58: Valor Mcia.
J60: SI
I61: C.O.
J63: =P56 -> 0.15
I64: IGI
A68: Seccion III. Informacion de Transporte (Costo 1 & 2)
J74: =S83 -> UR
I75: Remitente
J77: =S80 -> Juarez
I78: Suc. Destino | O78: INFORMACION SECCION III A | R78: INFORMACION SECCION III B | U78: BUSQUEDA DE COSTO TRANSPORTE 1
O79: SUCURSAL | P79: =P50 -> Juarez | R79: SUCURSAL | S79: =P79 -> Juarez | U79: COINCIDIR ADUANA/SUCURSAL | V79: =MATCH($P$84,'Fletes Proveedor'!C95:C128,0) -> 25
J80: =S84 -> Robot industrial para manipulación de mercancia con sus accesorios | O80: ADUANA | P80: =P51 -> El Paso | R80: DESTINO | S80: =P35 -> Juarez | U80: COINCIDIR TIPO TRANSPORTE | V80: =MATCH($P$87,'Fletes Proveedor'!D94:G94,0) -> 2
I81: Mercancía | O81: A.A. | P81: =P52 -> MARON | R81: ADUANA | S81: =P80 -> El Paso | U81: INDICE | V81: =INDEX('Fletes Proveedor'!D95:G128,MATCH($P$84,'Fletes Proveedor'!C95:C128,0),MATCH($P$87,'Fletes Proveedor'!D94:G94,0)) -> 2764
O82: PROVEEDOR | P82: =P53 -> UR | R82: A.A. | S82: =P81 -> MARON
J83: Embalaje URe | O83: PRODUCTO | P83: =P54 -> Robot industrial para manipulación de mercancia con sus accesorios | R83: PROVEEDOR | S83: =P82 -> UR
I84: Peso Libras | O84: RUTA | P84: =CONCATENATE(P82,P80) -> UREl Paso | R84: PRODUCTO | S84: =P83 -> Robot industrial para manipulación de mercancia con sus accesorios
...

Sheet NOTAS
B4: NOTAS:
B5: 1 | C5: Instrucciones de envio inbond
B6: 2 | C6: Instrucciones envio para importacion consolidada
B7: 3 | C7: *Revisar importaciones por marca para cumplir con el CLOG
B8: 4
B9: 5
B10: 6
B11: 7
B12: 8
B13: 9
B14: 10
B15: 11
B16: 12
B17: 13
B18: 14
B19: 15
